Workbook

Sheet UT1 (1273)
A1: Yıl | B1: Ay | C1: Fatura Tutarı TL | F1: Tüketim | J1: GES Üretim | K1: 1. Boyama Miktarı | L1: Reproses Miktarı | M1: Re-proses % | N1: ∑ Boyama Miktarı | O1: ∑ Paket. Miktarı | P1: ∑ İşçilik | Q1: ∑ Kişi Sayısı | R1: Kişi Başı Üretim kg | S1: Buhar K. Ç. Gün | T1: Günlük Boyama M. | U1: Yedek İşletme Üretim kg | V1: Kur: TL/$ | W1: Fatura | X1: Fatura usd | Y1: Fatura usd | Z1: Fatura usd | AA1: İplik Kg Başına Maliyet ($/kg) | AG1: İplik Kg Başına Tüketim (∑Boyama) | AJ1: Enerji Birim Fiyatları | AN1: Enerji Birim Fiyatları | AR1: =HYPERLINK("https://www.worldweatheronline.com/yakapinar-weather-averages/adana/tr.aspx","Ortalama Güneşlenme Süresi-Saat") -> Ortalama Güneşlenme Süresi-Saat
C2: DG-015 | D2: S060 | E2: E0060 | F2: Dgaz Sm3 | G2: Su m3 | H2: Atık Su m3 | I2: Elektrik kW | J2: Elektrik kW | W2: Enerji | X2: Doğalgaz | Y2: Su | Z2: Elektrik | AA2: Doğalgaz | AB2: Su | AC2: Elektrik | AD2: Toplam Enerji | AE2: Tamirsiz Enerji | AF2: Tamirsiz İşçilik | AG2: Dgaz Sm3 | AH2: Su ton | AI2: Elektrik kW | AJ2: Dgaz TL/Sm3 | AK2: Su TL/m3 | AL2: Elk TL/kW | AM2: OSB E TL/kW | AN2: Dgaz $/Sm3 | AO2: Su $/m3 | AP2: Elk $/kW | AQ2: OSB E $/kW
A3: 2011 | B3: 1 | C3: 113760.37 | D3: 24166.03 | E3: 54000.94 | F3: 196891.45 | G3: 37931 | I3: 312642 | K3: =N3-L3 -> 283705 | L3: 50526 | M3: =L3/N3 -> 0.1511709 | N3: 334231 | O3: 326795 | R3: =O3/Q3 -> #DIV/0! | S3: 28 | T3: =N3/S3 -> 11936.821 | U3: 13347 | V3: 1.598 | W3: =SUM(C3:E3)/V3 -> 120104.72 | X3: =C3/$V3 -> 71189.218 | Y3: =D3/$V3 -> 15122.672 | Z3: =E3/$V3 -> 33792.829 | AA3: =C3/((N3+U3)*V3) -> 0.20481509 | AB3: =D3/((N3+U3)*V3) -> 0.043508715 | AC3: =E3/((N3+U3)*V3) -> 0.097223727 | AD3: =(C3+D3+E3)/((N3+U3)*V3) -> 0.34554753 | AE3: =(C3+D3+E3)/((K3+U3)*V3) -> 0.4043222 | AG3: =F3/($N3+$U3) -> 0.56646695 | AH3: =G3/($N3+$U3) -> 0.10912946 | AI3: =I3/($N3+$U3) -> 0.89948731 | AJ3: =C3/F3 -> 0.57778217 | AK3: =D3/G3 -> 0.63710501 | AL3: =E3/I3 -> 0.17272452 | AN3: =AJ3/$V3 -> 0.36156582 | AO3: =AK3/$V3 -> 0.39868899 | AP3: =AL3/$V3 -> 0.10808794 | AQ3: =AM3/$V3 -> 0
A4: 2011 | B4: 2 | C4: 108012.1 | D4: 21027.95 | E4: 62620.68 | F4: 186942.56 | G4: 32437 | I4: 311526 | K4: =N4-L4 -> 306814 | L4: 48169 | M4: =L4/N4 -> 0.13569382 | N4: 354983 | O4: 322974 | R4: =O4/Q4 -> #DIV/0! | S4: 27 | T4: =N4/S4 -> 13147.519 | U4: 7119 | V4: 1.5917 | W4: =SUM(C4:E4)/V4 -> 120412.6 | X4: =C4/$V4 -> 67859.584 | Y4: =D4/$V4 -> 13211.001 | Z4: =E4/$V4 -> 39342.012 | AA4: =C4/((N4+U4)*V4) -> 0.18740461 | AB4: =D4/((N4+U4)*V4) -> 0.036484197 | AC4: =E4/((N4+U4)*V4) -> 0.10864898 | AD4: =(C4+D4+E4)/((N4+U4)*V4) -> 0.33253778 | AE4: =(C4+D4+E4)/((K4+U4)*V4) -> 0.38356145 | AG4: =F4/($N4+$U4) -> 0.51627044 | AH4: =G4/($N4+$U4) -> 0.089579732 | AI4: =I4/($N4+$U4) -> 0.86032665 | AJ4: =C4/F4 -> 0.57778229 | AK4: =D4/G4 -> 0.64827049 | AL4: =E4/I4 -> 0.20101269 | AN4: =AJ4/$V4 -> 0.36299698 | AO4: =AK4/$V4 -> 0.40728183 | AP4: =AL4/$V4 -> 0.12628805 | AQ4: =AM4/$V4 -> 0
A5: 2011 | B5: 3 | C5: 117004.07 | D5: 22130.4 | E5: 56619.22 | F5: 202505.46 | G5: 34710 | I5: 330822 | K5: =N5-L5 -> 366167 | L5: 50916 | M5: =L5/N5 -> 0.12207642 | N5: 417083 | O5: 402166 | R5: =O5/Q5 -> #DIV/0! | S5: 30 | T5: =N5/S5 -> 13902.767 | U5: 5627 | V5: 1.5352 | W5: =SUM(C5:E5)/V5 -> 127510.22 | X5: =C5/$V5 -> 76214.22 | Y5: =D5/$V5 -> 14415.32 | Z5: =E5/$V5 -> 36880.68 | AA5: =C5/((N5+U5)*V5) -> 0.18029907 | AB5: =D5/((N5+U5)*V5) -> 0.034102152 | AC5: =E5/((N5+U5)*V5) -> 0.087248184 | AD5: =(C5+D5+E5)/((N5+U5)*V5) -> 0.30164941 | AE5: =(C5+D5+E5)/((K5+U5)*V5) -> 0.34295933 | AG5: =F5/($N5+$U5) -> 0.47906475 | AH5: =G5/($N5+$U5) -> 0.082113033 | AI5: =I5/($N5+$U5) -> 0.78262166 | AJ5: =C5/F5 -> 0.5777823 | AK5: =D5/G5 -> 0.63757995 | AL5: =E5/I5 -> 0.17114708 | AN5: =AJ5/$V5 -> 0.37635637 | AO5: =AK5/$V5 -> 0.41530742 | AP5: =AL5/$V5 -> 0.11148195 | AQ5: =AM5/$V5 -> 0
A6: 2011 | B6: 4 | C6: 90682.37 | D6: 18797.2 | E6: 49591.51 | F6: 156949.04 | G6: 29429 | I6: 289638 | K6: =N6-L6 -> 282950 | L6: 40782 | M6: =L6/N6 -> 0.12597457 | N6: 323732 | O6: 350526 | R6: =O6/Q6 -> #DIV/0! | S6: 24 | T6: =N6/S6 -> 13488.833 | U6: 5186 | V6: 1.513 | W6: =SUM(C6:E6)/V6 -> 105136.21 | X6: =C6/$V6 -> 59935.473 | Y6: =D6/$V6 -> 12423.794 | Z6: =E6/$V6 -> 32776.94 | AA6: =C6/((N6+U6)*V6) -> 0.18222011 | AB6: =D6/((N6+U6)*V6) -> 0.037771705 | AC6: =E6/((N6+U6)*V6) -> 0.099650794 | AD6: =(C6+D6+E6)/((N6+U6)*V6) -> 0.3196426 | AE6: =(C6+D6+E6)/((K6+U6)*V6) -> 0.36488397 | AG6: =F6/($N6+$U6) -> 0.47716768 | AH6: =G6/($N6+$U6) -> 0.089472148 | AI6: =I6/($N6+$U6) -> 0.88057814 | AJ6: =C6/F6 -> 0.57778225 | AK6: =D6/G6 -> 0.6387305 | AL6: =E6/I6 -> 0.17121894 | AN6: =AJ6/$V6 -> 0.38187855 | AO6: =AK6/$V6 -> 0.4221616 | AP6: =AL6/$V6 -> 0.11316519 | AQ6: =AM6/$V6 -> 0
A7: 2011 | B7: 5 | C7: 75073.78 | D7: 15741 | E7: 39772.87 | F7: 129934.37 | G7: 24587 | I7: 232938 | K7: =N7-L7 -> 190741 | L7: 17933 | M7: =L7/N7 -> 0.085937874 | N7: 208674 | O7: 259329 | R7: =O7/Q7 -> #DIV/0! | S7: 28 | T7: =N7/S7 -> 7452.6429 | U7: 8346 | V7: 1.5848 | W7: =SUM(C7:E7)/V7 -> 82400.082 | X7: =C7/$V7 -> 47371.138 | Y7: =D7/$V7 -> 9932.4836 | Z7: =E7/$V7 -> 25096.46 | AA7: =C7/((N7+U7)*V7) -> 0.21828006 | AB7: =D7/((N7+U7)*V7) -> 0.045767596 | AC7: =E7/((N7+U7)*V7) -> 0.11564123 | AD7: =(C7+D7+E7)/((N7+U7)*V7) -> 0.37968889 | AE7: =(C7+D7+E7)/((K7+U7)*V7) -> 0.41388982 | AG7: =F7/($N7+$U7) -> 0.59872072 | AH7: =G7/($N7+$U7) -> 0.11329371 | AI7: =I7/($N7+$U7) -> 1.0733481 | AJ7: =C7/F7 -> 0.57778231 | AK7: =D7/G7 -> 0.64021637 | AL7: =E7/I7 -> 0.17074445 | AN7: =AJ7/$V7 -> 0.36457743 | AO7: =AK7/$V7 -> 0.40397298 | AP7: =AL7/$V7 -> 0.1077388 | AQ7: =AM7/$V7 -> 0
A8: 2011 | B8: 6 | C8: 82554.62 | D8: 19719.6 | E8: 45305.86 | F8: 142881.88 | G8: 30896 | I8: 263484 | K8: =N8-L8 -> 244784 | L8: 32384 | M8: =L8/N8 -> 0.11683888 | N8: 277168 | O8: 292469 | R8: =O8/Q8 -> #DIV/0! | S8: 29 | T8: =N8/S8 -> 9557.5172 | U8: 4272 | V8: 1.6146 | W8: =SUM(C8:E8)/V8 -> 91403.493 | X8: =C8/$V8 -> 51130.076 | Y8: =D8/$V8 -> 12213.304 | Z8: =E8/$V8 -> 28060.114 | AA8: =C8/((N8+U8)*V8) -> 0.18167309 | AB8: =D8/((N8+U8)*V8) -> 0.043395763 | AC8: =E8/((N8+U8)*V8) -> 0.09970194 | AD8: =(C8+D8+E8)/((N8+U8)*V8) -> 0.3247708 | AE8: =(C8+D8+E8)/((K8+U8)*V8) -> 0.36699976 | AG8: =F8/($N8+$U8) -> 0.5076815 | AH8: =G8/($N8+$U8) -> 0.10977828 | AI8: =I8/($N8+$U8) -> 0.93619955 | AJ8: =C8/F8 -> 0.57778229 | AK8: =D8/G8 -> 0.63825738 | AL8: =E8/I8 -> 0.17194919 | AN8: =AJ8/$V8 -> 0.35784856 | AO8: =AK8/$V8 -> 0.39530372 | AP8: =AL8/$V8 -> 0.10649646 | AQ8: =AM8/$V8 -> 0
A9: 2011 | B9: 7 | C9: 81787.84 | D9: 21870 | E9: 48939.24 | F9: 141554.79 | G9: 32179 | I9: 284922 | K9: =N9-L9 -> 235284 | L9: 15291 | M9: =L9/N9 -> 0.061023646 | N9: 250575 | O9: 287759 | R9: =O9/Q9 -> #DIV/0! | S9: 29 | T9: =N9/S9 -> 8640.5172 | U9: 12154 | V9: 1.6721 | W9: =SUM(C9:E9)/V9 -> 91260.738 | X9: =C9/$V9 -> 48913.247 | Y9: =D9/$V9 -> 13079.361 | Z9: =E9/$V9 -> 29268.13 | AA9: =C9/((N9+U9)*V9) -> 0.18617376 | AB9: =D9/((N9+U9)*V9) -> 0.049782709 | AC9: =E9/((N9+U9)*V9) -> 0.11140045 | AD9: =(C9+D9+E9)/((N9+U9)*V9) -> 0.34735693 | AE9: =(C9+D9+E9)/((K9+U9)*V9) -> 0.36882265 | AG9: =F9/($N9+$U9) -> 0.53878632 | AH9: =G9/($N9+$U9) -> 0.12247982 | AI9: =I9/($N9+$U9) -> 1.0844711 | AJ9: =C9/F9 -> 0.57778221 | AK9: =D9/G9 -> 0.67963579 | AL9: =E9/I9 -> 0.17176364 | AN9: =AJ9/$V9 -> 0.34554286 | AO9: =AK9/$V9 -> 0.40645642 | AP9: =AL9/$V9 -> 0.10272331 | AQ9: =AM9/$V9 -> 0
A10: 2011 | B10: 8 | C10: 69949.75 | D10: 19631.81 | E10: 45204.6 | F10: 119914.41 | G10: 29280 | I10: 264204 | K10: =N10-L10 -> 257171 | L10: 11289 | M10: =L10/N10 -> 0.042050957 | N10: 268460 | O10: 296090 | R10: =O10/Q10 -> #DIV/0! | S10: 28 | T10: =N10/S10 -> 9587.8571 | U10: 10022 | V10: 1.7442 | W10: =SUM(C10:E10)/V10 -> 77276.78 | X10: =C10/$V10 -> 40104.202 | Y10: =D10/$V10 -> 11255.481 | Z10: =E10/$V10 -> 25917.097 | AA10: =C10/((N10+U10)*V10) -> 0.14401003 | AB10: =D10/((N10+U10)*V10) -> 0.040417266 | AC10: =E10/((N10+U10)*V10) -> 0.093065608 | AD10: =(C10+D10+E10)/((N10+U10)*V10) -> 0.27749291 | AE10: =(C10+D10+E10)/((K10+U10)*V10) -> 0.28921708 | AG10: =F10/($N10+$U10) -> 0.43060022 | AH10: =G10/($N10+$U10) -> 0.10514145 | AI10: =I10/($N10+$U10) -> 0.94872918 | AJ10: =C10/F10 -> 0.58333064 | AK10: =D10/G10 -> 0.67048531 | AL10: =E10/I10 -> 0.17109733 | AN10: =AJ10/$V10 -> 0.33444023 | AO10: =AK10/$V10 -> 0.3844085 | AP10: =AL10/$V10 -> 0.09809502 | AQ10: =AM10/$V10 -> 0
A11: 2011 | B11: 9 | C11: 96608.57 | D11: 22936.1 | E11: 45326.42 | F11: 165615.46 | G11: 34268 | I11: 267858 | K11: =N11-L11 -> 261817 | L11: 16419 | M11: =L11/N11 -> 0.059011055 | N11: 278236 | O11: 325275 | R11: =O11/Q11 -> #DIV/0! | S11: 29 | T11: =N11/S11 -> 9594.3448 | U11: 11217 | V11: 1.8499 | W11: =SUM(C11:E11)/V11 -> 89124.326 | X11: =C11/$V11 -> 52223.672 | Y11: =D11/$V11 -> 12398.562 | Z11: =E11/$V11 -> 24502.092 | AA11: =C11/((N11+U11)*V11) -> 0.18042194 | AB11: =D11/((N11+U11)*V11) -> 0.042834457 | AC11: =E11/((N11+U11)*V11) -> 0.084649639 | AD11: =(C11+D11+E11)/((N11+U11)*V11) -> 0.30790604 | AE11: =(C11+D11+E11)/((K11+U11)*V11) -> 0.32642208 | AG11: =F11/($N11+$U11) -> 0.57216702 | AH11: =G11/($N11+$U11) -> 0.11838882 | AI11: =I11/($N11+$U11) -> 0.92539376 | AJ11: =C11/F11 -> 0.58333063 | AK11: =D11/G11 -> 0.6693154 | AL11: =E11/I11 -> 0.16921809 | AN11: =AJ11/$V11 -> 0.3153309 | AO11: =AK11/$V11 -> 0.36181166 | AP11: =AL11/$V11 -> 0.091474184 | AQ11: =AM11/$V11 -> 0
A12: 2011 | B12: 10 | C12: 112225.71 | D12: 23638.07 | E12: 54322.35 | F12: 168315.24 | G12: 35315 | I12: 311454 | K12: =N12-L12 -> 306349 | L12: 13807 | M12: =L12/N12 -> 0.043125851 | N12: 320156 | O12: 367797 | R12: =O12/Q12 -> #DIV/0! | S12: 28 | T12: =N12/S12 -> 11434.143 | U12: 22484 | V12: 1.7446 | W12: =SUM(C12:E12)/V12 -> 109014.18 | X12: =C12/$V12 -> 64327.473 | Y12: =D12/$V12 -> 13549.278 | Z12: =E12/$V12 -> 31137.424 | AA12: =C12/((N12+U12)*V12) -> 0.1877407 | AB12: =D12/((N12+U12)*V12) -> 0.039543771 | AC12: =E12/((N12+U12)*V12) -> 0.090875041 | AD12: =(C12+D12+E12)/((N12+U12)*V12) -> 0.31815951 | AE12: =(C12+D12+E12)/((K12+U12)*V12) -> 0.33151835 | AG12: =F12/($N12+$U12) -> 0.49123056 | AH12: =G12/($N12+$U12) -> 0.10306736 | AI12: =I12/($N12+$U12) -> 0.90898319 | AJ12: =C12/F12 -> 0.66675905 | AK12: =D12/G12 -> 0.66934929 | AL12: =E12/I12 -> 0.17441532 | AN12: =AJ12/$V12 -> 0.38218449 | AO12: =AK12/$V12 -> 0.3836692 | AP12: =AL12/$V12 -> 0.099974391 | AQ12: =AM12/$V12 -> 0
A13: 2011 | B13: 11 | C13: 109496.09 | D13: 21945.6 | E13: 47541.09 | F13: 164221.4 | G13: 32766 | I13: 272574 | K13: =N13-L13 -> 273053 | L13: 21306 | M13: =L13/N13 -> 0.072381004 | N13: 294359 | O13: 297995 | R13: =O13/Q13 -> #DIV/0! | S13: 24 | T13: =N13/S13 -> 12264.958 | U13: 19271 | V13: 1.8396 | W13: =SUM(C13:E13)/V13 -> 97294.401 | X13: =C13/$V13 -> 59521.684 | Y13: =D13/$V13 -> 11929.55 | Z13: =E13/$V13 -> 25843.167 | AA13: =C13/((N13+U13)*V13) -> 0.18978313 | AB13: =D13/((N13+U13)*V13) -> 0.038037018 | AC13: =E13/((N13+U13)*V13) -> 0.082400175 | AD13: =(C13+D13+E13)/((N13+U13)*V13) -> 0.31022033 | AE13: =(C13+D13+E13)/((K13+U13)*V13) -> 0.3328307 | AG13: =F13/($N13+$U13) -> 0.52361509 | AH13: =G13/($N13+$U13) -> 0.10447342 | AI13: =I13/($N13+$U13) -> 0.86909416 | AJ13: =C13/F13 -> 0.66675896 | AK13: =D13/G13 -> 0.66976744 | AL13: =E13/I13 -> 0.17441535 | AN13: =AJ13/$V13 -> 0.36244779 | AO13: =AK13/$V13 -> 0.36408319 | AP13: =AL13/$V13 -> 0.094811563 | AQ13: =AM13/$V13 -> 0
A14: 2011 | B14: 12 | C14: 128221.3 | D14: 25883.28 | E14: 58952.09 | F14: 192305.32 | G14: 38622 | I14: 326556 | K14: =N14-L14 -> 315048 | L14: 27863 | M14: =L14/N14 -> 0.08125432 | N14: 342911 | O14: 366334 | R14: =O14/Q14 -> #DIV/0! | S14: 29 | T14: =N14/S14 -> 11824.517 | U14: 16265 | V14: 1.8876 | W14: =SUM(C14:E14)/V14 -> 112871.73 | X14: =C14/$V14 -> 67928.216 | Y14: =D14/$V14 -> 13712.27 | Z14: =E14/$V14 -> 31231.241 | AA14: =C14/((N14+U14)*V14) -> 0.18912237 | AB14: =D14/((N14+U14)*V14) -> 0.038177021 | AC14: =E14/((N14+U14)*V14) -> 0.086952471 | AD14: =(C14+D14+E14)/((N14+U14)*V14) -> 0.31425186 | AE14: =(C14+D14+E14)/((K14+U14)*V14) -> 0.34068004 | AG14: =F14/($N14+$U14) -> 0.53540693 | AH14: =G14/($N14+$U14) -> 0.10752946 | AI14: =I14/($N14+$U14) -> 0.90918101 | AJ14: =C14/F14 -> 0.66675899 | AK14: =D14/G14 -> 0.67016933 | AL14: =E14/I14 -> 0.18052674 | AN14: =AJ14/$V14 -> 0.35323108 | AO14: =AK14/$V14 -> 0.35503779 | AP14: =AL14/$V14 -> 0.095638239 | AQ14: =AM14/$V14 -> 0
A15: 2012 | B15: 1 | C15: 133831.58 | D15: 25483.86 | E15: 60141.21 | F15: 200719.57 | G15: 38096 | I15: 343044 | K15: =N15-L15 -> 324458 | L15: 21575 | M15: =L15/N15 -> 0.062349545 | N15: 346033 | O15: 355922 | R15: =O15/Q15 -> #DIV/0! | S15: 25 | T15: =N15/S15 -> 13841.32 | U15: 19024 | V15: ='$'!C2 -> 1.842267 | W15: =SUM(C15:E15)/V15 -> 119123.15 | X15: =C15/$V15 -> 72645.051 | Y15: =D15/$V15 -> 13832.881 | Z15: =E15/$V15 -> 32645.219 | AA15: =C15/((N15+U15)*V15) -> 0.19899646 | AB15: =D15/((N15+U15)*V15) -> 0.037892386 | AC15: =E15/((N15+U15)*V15) -> 0.089424992 | AD15: =(C15+D15+E15)/((N15+U15)*V15) -> 0.32631384 | AE15: =(C15+D15+E15)/((K15+U15)*V15) -> 0.34681046 | AG15: =F15/($N15+$U15) -> 0.54983077 | AH15: =G15/($N15+$U15) -> 0.10435631 | AI15: =I15/($N15+$U15) -> 0.93969983 | AJ15: =C15/F15 -> 0.666759 | AK15: =D15/G15 -> 0.66893795 | AL15: =E15/I15 -> 0.17531632 | AN15: =AJ15/$V15 -> 0.36192311 | AO15: =AK15/$V15 -> 0.36310586 | AP15: =AL15/$V15 -> 0.095163359 | AQ15: =AM15/$V15 -> 0
A16: 2012 | B16: 2 | C16: 121406.37 | D16: 24301.91 | E16: 53775.24 | F16: 182084.33 | G16: 36315 | I16: 306732.8 | K16: =N16-L16 -> 294148 | L16: 14791 | M16: =L16/N16 -> 0.047876765 | N16: 308939 | O16: 336318 | R16: =O16/Q16 -> #DIV/0! | S16: 23 | T16: =N16/S16 -> 13432.13 | U16: 17049 | V16: ='$'!C3 -> 1.757901 | W16: =SUM(C16:E16)/V16 -> 113478.24 | X16: =C16/$V16 -> 69063.258 | Y16: =D16/$V16 -> 13824.391 | Z16: =E16/$V16 -> 30590.596 | AA16: =C16/((N16+U16)*V16) -> 0.21185828 | AB16: =D16/((N16+U16)*V16) -> 0.042407667 | AC16: =E16/((N16+U16)*V16) -> 0.093839639 | AD16: =(C16+D16+E16)/((N16+U16)*V16) -> 0.34810559 | AE16: =(C16+D16+E16)/((K16+U16)*V16) -> 0.36465083 | AG16: =F16/($N16+$U16) -> 0.55856145 | AH16: =G16/($N16+$U16) -> 0.11139981 | AI16: =I16/($N16+$U16) -> 0.9409328 | AJ16: =C16/F16 -> 0.66675902 | AK16: =D16/G16 -> 0.66919758 | AL16: =E16/I16 -> 0.17531624 | AN16: =AJ16/$V16 -> 0.3792927 | AO16: =AK16/$V16 -> 0.3806799 | AP16: =AL16/$V16 -> 0.099730438 | AQ16: =AM16/$V16 -> 0
A17: 2012 | B17: 3 | C17: 112741.37 | D17: 24108.7 | E17: 58407.14 | F17: 166690 | G17: 36024 | I17: 333153 | K17: =N17-L17 -> 299083 | L17: 13861 | M17: =L17/N17 -> 0.04429227 | N17: 312944 | O17: 374185 | R17: =O17/Q17 -> #DIV/0! | S17: 26 | T17: =N17/S17 -> 12036.308 | U17: 19955 | V17: ='$'!C4 -> 1.789832 | W17: =SUM(C17:E17)/V17 -> 109092.48 | X17: =C17/$V17 -> 62989.917 | Y17: =D17/$V17 -> 13469.812 | Z17: =E17/$V17 -> 32632.75 | AA17: =C17/((N17+U17)*V17) -> 0.1892163 | AB17: =D17/((N17+U17)*V17) -> 0.040462157 | AC17: =E17/((N17+U17)*V17) -> 0.098025978 | AD17: =(C17+D17+E17)/((N17+U17)*V17) -> 0.32770444 | AE17: =(C17+D17+E17)/((K17+U17)*V17) -> 0.34194196 | AG17: =F17/($N17+$U17) -> 0.50072244 | AH17: =G17/($N17+$U17) -> 0.108213 | AI17: =I17/($N17+$U17) -> 1.000763 | AJ17: =C17/F17 -> 0.67635353 | AK17: =D17/G17 -> 0.66923995 | AL17: =E17/I17 -> 0.17531627 | AN17: =AJ17/$V17 -> 0.3778866 | AO17: =AK17/$V17 -> 0.37391216 | AP17: =AL17/$V17 -> 0.097951241 | AQ17: =AM17/$V17 -> 0
A18: 2012 | B18: 4 | C18: 116585.81 | D18: 21747.15 | E18: 53468.16 | F18: 144612.23 | G18: 32467 | I18: 278470.8 | K18: =N18-L18 -> 284925 | L18: 7034 | M18: =L18/N18 -> 0.024092424 | N18: 291959 | O18: 321200 | R18: =O18/Q18 -> #DIV/0! | S18: 25 | T18: =N18/S18 -> 11678.36 | U18: 15200 | V18: ='$'!C5 -> 1.787371 | W18: =SUM(C18:E18)/V18 -> 107309.07 | X18: =C18/$V18 -> 65227.538 | Y18: =D18/$V18 -> 12167.116 | Z18: =E18/$V18 -> 29914.416 | AA18: =C18/((N18+U18)*V18) -> 0.21235757 | AB18: =D18/((N18+U18)*V18) -> 0.039611784 | AC18: =E18/((N18+U18)*V18) -> 0.097390655 | AD18: =(C18+D18+E18)/((N18+U18)*V18) -> 0.34936001 | AE18: =(C18+D18+E18)/((K18+U18)*V18) -> 0.35754792 | AG18: =F18/($N18+$U18) -> 0.47080577 | AH18: =G18/($N18+$U18) -> 0.10570096 | AI18: =I18/($N18+$U18) -> 0.90660147 | AJ18: =C18/F18 -> 0.80619606 | AK18: =D18/G18 -> 0.66982321 | AL18: =E18/I18 -> 0.19200634 | AN18: =AJ18/$V18 -> 0.45105133 | AO18: =AK18/$V18 -> 0.37475331 | AP18: =AL18/$V18 -> 0.10742389 | AQ18: =AM18/$V18 -> 0
A19: 2012 | B19: 5 | C19: 111941.25 | D19: 22977.76 | E19: 51426.98 | F19: 138851.17 | G19: 34215 | I19: 267840 | K19: =N19-L19 -> 256625 | L19: 13645 | M19: =L19/N19 -> 0.05048655 | N19: 270270 | O19: 290690 | R19: =O19/Q19 -> #DIV/0! | S19: 26 | T19: =N19/S19 -> 10395 | U19: 6535 | V19: ='$'!C6 -> 1.809909 | W19: =SUM(C19:E19)/V19 -> 102958.76 | X19: =C19/$V19 -> 61849.104 | Y19: =D19/$V19 -> 12695.533 | Z19: =E19/$V19 -> 28414.125 | AA19: =C19/((N19+U19)*V19) -> 0.22343926 | AB19: =D19/((N19+U19)*V19) -> 0.045864538 | AC19: =E19/((N19+U19)*V19) -> 0.10265033 | AD19: =(C19+D19+E19)/((N19+U19)*V19) -> 0.37195413 | AE19: =(C19+D19+E19)/((K19+U19)*V19) -> 0.39124017 | AG19: =F19/($N19+$U19) -> 0.50162089 | AH19: =G19/($N19+$U19) -> 0.12360687 | AI19: =I19/($N19+$U19) -> 0.96761258 | AJ19: =C19/F19 -> 0.80619594 | AK19: =D19/G19 -> 0.67156978 | AL19: =E19/I19 -> 0.19200635 | AN19: =AJ19/$V19 -> 0.44543452 | AO19: =AK19/$V19 -> 0.37105168 | AP19: =AL19/$V19 -> 0.10608619 | AQ19: =AM19/$V19 -> 0
A20: 2012 | B20: 6 | C20: 89114.52 | D20: 17672.22 | E20: 46404.77 | F20: 110537.05 | G20: 26289 | I20: 231705 | K20: =N20-L20 -> 221455 | L20: 15008 | M20: =L20/N20 -> 0.063468703 | N20: 236463 | O20: 249571 | R20: =O20/Q20 -> #DIV/0! | S20: 25 | T20: =N20/S20 -> 9458.52 | U20: 5372 | V20: ='$'!C7 -> 1.822835 | W20: =SUM(C20:E20)/V20 -> 84040.25 | X20: =C20/$V20 -> 48887.87 | Y20: =D20/$V20 -> 9694.9093 | Z20: =E20/$V20 -> 25457.471 | AA20: =C20/((N20+U20)*V20) -> 0.20215382 | AB20: =D20/((N20+U20)*V20) -> 0.040088942 | AC20: =E20/((N20+U20)*V20) -> 0.10526794 | AD20: =(C20+D20+E20)/((N20+U20)*V20) -> 0.3475107 | AE20: =(C20+D20+E20)/((K20+U20)*V20) -> 0.37050373 | AG20: =F20/($N20+$U20) -> 0.45707631 | AH20: =G20/($N20+$U20) -> 0.10870635 | AI20: =I20/($N20+$U20) -> 0.95811194 | AJ20: =C20/F20 -> 0.80619593 | AK20: =D20/G20 -> 0.67222869 | AL20: =E20/I20 -> 0.20027522 | AN20: =AJ20/$V20 -> 0.44227587 | AO20: =AK20/$V20 -> 0.36878197 | AP20: =AL20/$V20 -> 0.10987019 | AQ20: =AM20/$V20 -> 0
A21: 2012 | B21: 7 | C21: 89448.46 | D21: 19337.21 | E21: 50074.94 | F21: 110951.25 | G21: 25565 | I21: 247093.2 | K21: =N21-L21 -> 223778 | L21: 9964 | M21: =L21/N21 -> 0.042628197 | N21: 233742 | O21: 250841 | R21: =O21/Q21 -> #DIV/0! | S21: 26 | T21: =N21/S21 -> 8990.0769 | U21: 14876 | V21: ='$'!C8 -> 1.811551 | W21: =SUM(C21:E21)/V21 -> 87693.148 | X21: =C21/$V21 -> 49376.727 | Y21: =D21/$V21 -> 10674.394 | Z21: =E21/$V21 -> 27642.026 | AA21: =C21/((N21+U21)*V21) -> 0.1986048 | AB21: =D21/((N21+U21)*V21) -> 0.042934922 | AC21: =E21/((N21+U21)*V21) -> 0.11118272 | AD21: =(C21+D21+E21)/((N21+U21)*V21) -> 0.35272244 | AE21: =(C21+D21+E21)/((K21+U21)*V21) -> 0.36744889 | AG21: =F21/($N21+$U21) -> 0.44627199 | AH21: =G21/($N21+$U21) -> 0.10282844 | AI21: =I21/($N21+$U21) -> 0.9938669 | AJ21: =C21/F21 -> 0.80619605 | AK21: =D21/G21 -> 0.7563939 | AL21: =E21/I21 -> 0.20265608 | AN21: =AJ21/$V21 -> 0.44503084 | AO21: =AK21/$V21 -> 0.41753939 | AP21: =AL21/$V21 -> 0.11186883 | AQ21: =AM21/$V21 -> 0
A22: 2012 | B22: 8 | C22: 95960 | D22: 21411.85 | E22: 50082.6 | F22: 119033.06 | G22: 28335 | I22: 247131 | K22: =N22-L22 -> 234982 | L22: 10034 | M22: =L22/N22 -> 0.040952428 | N22: 245016 | O22: 266502 | R22: =O22/Q22 -> #DIV/0! | S22: 27 | T22: =N22/S22 -> 9074.6667 | U22: 11415 | V22: ='$'!C9 -> 1.794777 | W22: =SUM(C22:E22)/V22 -> 93300.978 | X22: =C22/$V22 -> 53466.252 | Y22: =D22/$V22 -> 11930.089 | Z22: =E22/$V22 -> 27904.637 | AA22: =C22/((N22+U22)*V22) -> 0.20850152 | AB22: =D22/((N22+U22)*V22) -> 0.046523585 | AC22: =E22/((N22+U22)*V22) -> 0.10881928 | AD22: =(C22+D22+E22)/((N22+U22)*V22) -> 0.36384438 | AE22: =(C22+D22+E22)/((K22+U22)*V22) -> 0.37866118 | AG22: =F22/($N22+$U22) -> 0.46419138 | AH22: =G22/($N22+$U22) -> 0.11049756 | AI22: =I22/($N22+$U22) -> 0.96373293 | AJ22: =C22/F22 -> 0.80616259 | AK22: =D22/G22 -> 0.7556679 | AL22: =E22/I22 -> 0.20265608 | AN22: =AJ22/$V22 -> 0.44917145 | AO22: =AK22/$V22 -> 0.42103721 | AP22: =AL22/$V22 -> 0.11291435 | AQ22: =AM22/$V22 -> 0
A23: 2012 | B23: 9 | C23: 106772.3 | D23: 23886.6 | E23: 56467.7 | F23: 132440 | G23: 31631 | I23: 278638.2 | K23: =N23-L23 -> 257320 | L23: 20716 | M23: =L23/N23 -> 0.074508337 | N23: 278036 | O23: 293592 | R23: =O23/Q23 -> #DIV/0! | S23: 27 | T23: =N23/S23 -> 10297.63 | U23: 12924 | V23: ='$'!C10 -> 1.801074 | W23: =SUM(C23:E23)/V23 -> 103897.23 | X23: =C23/$V23 -> 59282.573 | Y23: =D23/$V23 -> 13262.42 | Z23: =E23/$V23 -> 31352.238 | AA23: =C23/((N23+U23)*V23) -> 0.20374819 | AB23: =D23/((N23+U23)*V23) -> 0.045581592 | AC23: =E23/((N23+U23)*V23) -> 0.10775446 | AD23: =(C23+D23+E23)/((N23+U23)*V23) -> 0.35708424 | AE23: =(C23+D23+E23)/((K23+U23)*V23) -> 0.38445712 | AG23: =F23/($N23+$U23) -> 0.45518284 | AH23: =G23/($N23+$U23) -> 0.10871254 | AI23: =I23/($N23+$U23) -> 0.95765122 | AJ23: =C23/F23 -> 0.80619375 | AK23: =D23/G23 -> 0.75516424 | AL23: =E23/I23 -> 0.20265599 | AN23: =AJ23/$V23 -> 0.44761834 | AO23: =AK23/$V23 -> 0.41928551 | AP23: =AL23/$V23 -> 0.11251952 | AQ23: =AM23/$V23 -> 0
A24: 2012 | B24: 10 | C24: 120537 | D24: 24909.9 | E24: 52992.7 | F24: 135923.13 | G24: 33007 | I24: 244272.6 | K24: =N24-L24 -> 242823 | L24: 24260 | M24: =L24/N24 -> 0.090833187 | N24: 267083 | O24: 288011 | R24: =O24/Q24 -> #DIV/0! | S24: 24 | T24: =N24/S24 -> 11128.458 | U24: 13504 | V24: ='$'!C11 -> 1.80206 | W24: =SUM(C24:E24)/V24 -> 110118.2 | X24: =C24/$V24 -> 66888.45 | Y24: =D24/$V24 -> 13823.014 | Z24: =E24/$V24 -> 29406.735 | AA24: =C24/((N24+U24)*V24) -> 0.23838756 | AB24: =D24/((N24+U24)*V24) -> 0.049264626 | AC24: =E24/((N24+U24)*V24) -> 0.10480434 | AD24: =(C24+D24+E24)/((N24+U24)*V24) -> 0.39245652 | AE24: =(C24+D24+E24)/((K24+U24)*V24) -> 0.42960046 | AG24: =F24/($N24+$U24) -> 0.48442419 | AH24: =G24/($N24+$U24) -> 0.11763553 | AI24: =I24/($N24+$U24) -> 0.87057704 | AJ24: =C24/F24 -> 0.88680271 | AK24: =D24/G24 -> 0.75468537 | AL24: =E24/I24 -> 0.21694083 | AN24: =AJ24/$V24 -> 0.49210499 | AO24: =AK24/$V24 -> 0.41879037 | AP24: =AL24/$V24 -> 0.12038491 | AQ24: =AM24/$V24 -> 0
A25: 2012 | B25: 11 | C25: 133941.28 | D25: 20424.56 | E25: 54423.41 | F25: 151033.95 | G25: 27017 | I25: 250867.8 | K25: =N25-L25 -> 254074 | L25: 22254 | M25: =L25/N25 -> 0.080534727 | N25: 276328 | O25: 305084 | R25: =O25/Q25 -> #DIV/0! | S25: 24 | T25: =N25/S25 -> 11513.667 | U25: 18838 | V25: ='$'!C12 -> 1.793263 | W25: =SUM(C25:E25)/V25 -> 116429.8 | X25: =C25/$V25 -> 74691.375 | Y25: =D25/$V25 -> 11389.607 | Z25: =E25/$V25 -> 30348.817 | AA25: =C25/((N25+U25)*V25) -> 0.25304871 | AB25: =D25/((N25+U25)*V25) -> 0.038587122 | AC25: =E25/((N25+U25)*V25) -> 0.10281949 | AD25: =(C25+D25+E25)/((N25+U25)*V25) -> 0.39445532 | AE25: =(C25+D25+E25)/((K25+U25)*V25) -> 0.4266203 | AG25: =F25/($N25+$U25) -> 0.51169156 | AH25: =G25/($N25+$U25) -> 0.091531545 | AI25: =I25/($N25+$U25) -> 0.84992106 | AJ25: =C25/F25 -> 0.88682895 | AK25: =D25/G25 -> 0.75598919 | AL25: =E25/I25 -> 0.2169406 | AN25: =AJ25/$V25 -> 0.49453368 | AO25: =AK25/$V25 -> 0.42157185 | AP25: =AL25/$V25 -> 0.12097534 | AQ25: =AM25/$V25 -> 0
A26: 2012 | B26: 12 | C26: 137627.44 | D26: 21991.94 | E26: 53909.15 | F26: 155190.49 | G26: 29110 | I26: 248497.2 | K26: =N26-L26 -> 269728 | L26: 16728 | M26: =L26/N26 -> 0.058396403 | N26: 286456 | O26: 315993 | R26: =O26/Q26 -> #DIV/0! | S26: 25 | T26: =N26/S26 -> 11458.24 | U26: 20857 | V26: ='$'!C13 -> 1.787485 | W26: =SUM(C26:E26)/V26 -> 119457.52 | X26: =C26/$V26 -> 76995.018 | Y26: =D26/$V26 -> 12303.286 | Z26: =E26/$V26 -> 30159.218 | AA26: =C26/((N26+U26)*V26) -> 0.25054267 | AB26: =D26/((N26+U26)*V26) -> 0.040035034 | AC26: =E26/((N26+U26)*V26) -> 0.098138439 | AD26: =(C26+D26+E26)/((N26+U26)*V26) -> 0.38871614 | AE26: =(C26+D26+E26)/((K26+U26)*V26) -> 0.41109322 | AG26: =F26/($N26+$U26) -> 0.50499162 | AH26: =G26/($N26+$U26) -> 0.094724271 | AI26: =I26/($N26+$U26) -> 0.80861272 | AJ26: =C26/F26 -> 0.88682908 | AK26: =D26/G26 -> 0.75547716 | AL26: =E26/I26 -> 0.21694067 | AN26: =AJ26/$V26 -> 0.49613232 | AO26: =AK26/$V26 -> 0.42264811 | AP26: =AL26/$V26 -> 0.12136643 | AQ26: =AM26/$V26 -> 0
... A38: 2013 | B38: 12 | C38: 144901.35 | D38: 17593.48 | E38: 57320.02 | F38: 165007.89 | G38: 23236 | I38: 265726.8 | K38: =N38-L38 -> 327767 | L38: 46819 | M38: =L38/N38 -> 0.12498865 | N38: 374586 | O38: 346382 | R38: =O38/Q38 -> #DIV/0! | S38: 27 | T38: =N38/S38 -> 13873.556 | U38: 21500 | V38: ='$'!C25 -> 2.067259 | W38: =SUM(C38:E38)/V38 -> 106331.55 | X38: =C38/$V38 -> 70093.467 | Y38: =D38/$V38 -> 8510.535 | Z38: =E38/$V38 -> 27727.546 | AA38: =C38/((N38+U38)*V38) -> 0.17696527 | AB38: =D38/((N38+U38)*V38) -> 0.021486584 | AC38: =E38/((N38+U38)*V38) -> 0.070003854 | AD38: =(C38+D38+E38)/((N38+U38)*V38) -> 0.26845571 | AE38: =(C38+D38+E38)/((K38+U38)*V38) -> 0.30444201 | AG38: =F38/($N38+$U38) -> 0.41659612 | AH38: =G38/($N38+$U38) -> 0.058664028 | AI38: =I38/($N38+$U38) -> 0.67088158 | AJ38: =C38/F38 -> 0.87814801 | AK38: =D38/G38 -> 0.75716474 | AL38: =E38/I38 -> 0.21571035 | AN38: =AJ38/$V38 -> 0.42478858 | AO38: =AK38/$V38 -> 0.36626506 | AP38: =AL38/$V38 -> 0.10434607 | AQ38: =AM38/$V38 -> 0
A39: 2014 | B39: 1 | C39: 127934.63 | D39: 16162.53 | E39: 51983.86 | F39: 145686.88 | G39: 21325 | I39: 243129.6 | K39: =N39-L39 -> 265489 | L39: 36684 | M39: =L39/N39 -> 0.12140065 | N39: 302173 | O39: 299530 | P39: 255844 | Q39: 152 | R39: =O39/Q39 -> 1970.5921 | S39: 26 | T39: =N39/S39 -> 11622.038 | U39: 19300 | V39: ='$'!C26 -> 2.221045 | W39: =SUM(C39:E39)/V39 -> 88283.227 | X39: =C39/$V39 -> 57601.098 | Y39: =D39/$V39 -> 7276.9935 | Z39: =E39/$V39 -> 23405.136 | AA39: =C39/((N39+U39)*V39) -> 0.17917865 | AB39: =D39/((N39+U39)*V39) -> 0.022636406 | AC39: =E39/((N39+U39)*V39) -> 0.072805915 | AD39: =(C39+D39+E39)/((N39+U39)*V39) -> 0.27462097 | AE39: =(C39+D39+E39)/((K39+U39)*V39) -> 0.30999521 | AF39: =(P39/V39)/K39 -> 0.43388171 | AG39: =F39/($N39+$U39) -> 0.45318543 | AH39: =G39/($N39+$U39) -> 0.066335275 | AI39: =I39/($N39+$U39) -> 0.75629866 | AJ39: =C39/F39 -> 0.87814792 | AK39: =D39/G39 -> 0.75791465 | AL39: =E39/I39 -> 0.21381132 | AN39: =AJ39/$V39 -> 0.39537601 | AO39: =AK39/$V39 -> 0.34124237 | AP39: =AL39/$V39 -> 0.09626609 | AQ39: =AM39/$V39 -> 0
A40: 2014 | B40: 2 | C40: 111388.09 | D40: 15455.88 | E40: 51159.5 | F40: 126844.32 | G40: 20381 | I40: 239274 | K40: =N40-L40 -> 268978 | L40: 38284 | M40: =L40/N40 -> 0.12459725 | N40: 307262 | O40: 324366 | P40: 271774 | Q40: 189 | R40: =O40/Q40 -> 1716.2222 | S40: 25 | T40: =N40/S40 -> 12290.48 | U40: 16360 | V40: ='$'!C27 -> 2.206518 | W40: =SUM(C40:E40)/V40 -> 80671.66 | X40: =C40/$V40 -> 50481.387 | Y40: =D40/$V40 -> 7004.6471 | Z40: =E40/$V40 -> 23185.625 | AA40: =C40/((N40+U40)*V40) -> 0.15598874 | AB40: =D40/((N40+U40)*V40) -> 0.021644533 | AC40: =E40/((N40+U40)*V40) -> 0.071644157 | AD40: =(C40+D40+E40)/((N40+U40)*V40) -> 0.24927743 | AE40: =(C40+D40+E40)/((K40+U40)*V40) -> 0.28272316 | AF40: =(P40/V40)/K40 -> 0.45791374 | AG40: =F40/($N40+$U40) -> 0.39195209 | AH40: =G40/($N40+$U40) -> 0.062977795 | AI40: =I40/($N40+$U40) -> 0.73936259 | AJ40: =C40/F40 -> 0.87814803 | AK40: =D40/G40 -> 0.75834748 | AL40: =E40/I40 -> 0.21381136 | AN40: =AJ40/$V40 -> 0.39797909 | AO40: =AK40/$V40 -> 0.34368515 | AP40: =AL40/$V40 -> 0.096899895 | AQ40: =AM40/$V40 -> 0
A41: 2014 | B41: 3 | C41: 105817.6 | D41: 16157.2 | E41: 53320.85 | F41: 120500.87 | G41: 21316 | I41: 249382.8 | K41: =N41-L41 -> 258151 | L41: 24534 | M41: =L41/N41 -> 0.086789182 | N41: 282685 | O41: 298591 | P41: 273537 | Q41: 170 | R41: =O41/Q41 -> 1756.4176 | S41: 26 | T41: =N41/S41 -> 10872.5 | U41: 23500 | V41: ='$'!C28 -> 2.21216 | W41: =SUM(C41:E41)/V41 -> 79241.85 | X41: =C41/$V41 -> 47834.515 | Y41: =D41/$V41 -> 7303.8117 | Z41: =E41/$V41 -> 24103.523 | AA41: =C41/((N41+U41)*V41) -> 0.15622749 | AB41: =D41/((N41+U41)*V41) -> 0.023854244 | AC41: =E41/((N41+U41)*V41) -> 0.07872209 | AD41: =(C41+D41+E41)/((N41+U41)*V41) -> 0.25880383 | AE41: =(C41+D41+E41)/((K41+U41)*V41) -> 0.28134766 | AF41: =(P41/V41)/K41 -> 0.47898921 | AG41: =F41/($N41+$U41) -> 0.39355576 | AH41: =G41/($N41+$U41) -> 0.069618041 | AI41: =I41/($N41+$U41) -> 0.81448405 | AJ41: =C41/F41 -> 0.87814802 | AK41: =D41/G41 -> 0.75798461 | AL41: =E41/I41 -> 0.21381126 | AN41: =AJ41/$V41 -> 0.39696406 | AO41: =AK41/$V41 -> 0.34264457 | AP41: =AL41/$V41 -> 0.096652709 | AQ41: =AM41/$V41 -> 0
A42: 2014 | B42: 4 | C42: 92453.46 | D42: 15017.61 | E42: 44728.08 | F42: 105282.33 | G42: 19796 | I42: 209194.2 | K42: =N42-L42 -> 214967 | L42: 9499 | M42: =L42/N42 -> 0.042318213 | N42: 224466 | O42: 242297 | P42: 301209 | Q42: 176 | R42: =O42/Q42 -> 1376.6875 | S42: 28 | T42: =N42/S42 -> 8016.6429 | U42: 20200 | V42: ='$'!C29 -> 2.124484 | W42: =SUM(C42:E42)/V42 -> 71640.525 | X42: =C42/$V42 -> 43518.078 | Y42: =D42/$V42 -> 7068.8271 | Z42: =E42/$V42 -> 21053.621 | AA42: =C42/((N42+U42)*V42) -> 0.17786729 | AB42: =D42/((N42+U42)*V42) -> 0.028891742 | AC42: =E42/((N42+U42)*V42) -> 0.086050455 | AD42: =(C42+D42+E42)/((N42+U42)*V42) -> 0.29280948 | AE42: =(C42+D42+E42)/((K42+U42)*V42) -> 0.30463681 | AF42: =(P42/V42)/K42 -> 0.65954234 | AG42: =F42/($N42+$U42) -> 0.43031042 | AH42: =G42/($N42+$U42) -> 0.080910302 | AI42: =I42/($N42+$U42) -> 0.8550195 | AJ42: =C42/F42 -> 0.87814793 | AK42: =D42/G42 -> 0.75861841 | AL42: =E42/I42 -> 0.21381128 | AN42: =AJ42/$V42 -> 0.41334645 | AO42: =AK42/$V42 -> 0.35708361 | AP42: =AL42/$V42 -> 0.10064151 | AQ42: =AM42/$V42 -> 0
A43: 2014 | B43: 5 | C43: 92428.83 | D43: 16685.19 | E43: 50530.24 | F43: 105254.28 | G43: 22023 | I43: 236331 | K43: =N43-L43 -> 226364 | L43: 20665 | M43: =L43/N43 -> 0.083654146 | N43: 247029 | O43: 265210 | P43: 326302 | Q43: 174 | R43: =O43/Q43 -> 1524.1954 | S43: 27 | T43: =N43/S43 -> 9149.2222 | U43: 22638 | V43: ='$'!C30 -> 2.090432 | W43: =SUM(C43:E43)/V43 -> 76369.028 | X43: =C43/$V43 -> 44215.181 | Y43: =D43/$V43 -> 7981.6947 | Z43: =E43/$V43 -> 24172.152 | AA43: =C43/((N43+U43)*V43) -> 0.16396215 | AB43: =D43/((N43+U43)*V43) -> 0.029598337 | AC43: =E43/((N43+U43)*V43) -> 0.089637041 | AD43: =(C43+D43+E43)/((N43+U43)*V43) -> 0.28319753 | AE43: =(C43+D43+E43)/((K43+U43)*V43) -> 0.30670046 | AF43: =(P43/V43)/K43 -> 0.68956678 | AG43: =F43/($N43+$U43) -> 0.39031205 | AH43: =G43/($N43+$U43) -> 0.08166739 | AI43: =I43/($N43+$U43) -> 0.87638087 | AJ43: =C43/F43 -> 0.87814795 | AK43: =D43/G43 -> 0.75762566 | AL43: =E43/I43 -> 0.21381131 | AN43: =AJ43/$V43 -> 0.42007965 | AO43: =AK43/$V43 -> 0.3624254 | AP43: =AL43/$V43 -> 0.10228092 | AQ43: =AM43/$V43 -> 0
A44: 2014 | B44: 6 | C44: 93343.73 | D44: 16543.67 | E44: 54216.81 | F44: 106296.13 | G44: 21834 | I44: 253573.2 | K44: =N44-L44 -> 261451 | L44: 19440 | M44: =L44/N44 -> 0.069208341 | N44: 280891 | O44: 286121 | P44: 285636 | Q44: 172 | R44: =O44/Q44 -> 1663.4942 | S44: 25 | T44: =N44/S44 -> 11235.64 | U44: 25200 | V44: ='$'!C31 -> 2.118606 | W44: =SUM(C44:E44)/V44 -> 77458.579 | X44: =C44/$V44 -> 44059.032 | Y44: =D44/$V44 -> 7808.7525 | Z44: =E44/$V44 -> 25590.794 | AA44: =C44/((N44+U44)*V44) -> 0.14394096 | AB44: =D44/((N44+U44)*V44) -> 0.025511213 | AC44: =E44/((N44+U44)*V44) -> 0.083605183 | AD44: =(C44+D44+E44)/((N44+U44)*V44) -> 0.25305736 | AE44: =(C44+D44+E44)/((K44+U44)*V44) -> 0.27021911 | AF44: =(P44/V44)/K44 -> 0.51567068 | AG44: =F44/($N44+$U44) -> 0.3472697 | AH44: =G44/($N44+$U44) -> 0.071331728 | AI44: =I44/($N44+$U44) -> 0.82842423 | AJ44: =C44/F44 -> 0.87814796 | AK44: =D44/G44 -> 0.75770221 | AL44: =E44/I44 -> 0.21381128 | AN44: =AJ44/$V44 -> 0.41449329 | AO44: =AK44/$V44 -> 0.35764187 | AP44: =AL44/$V44 -> 0.10092074 | AQ44: =AM44/$V44 -> 0
A45: 2014 | B45: 7 | C45: 78040.75 | D45: 16448.06 | E45: 48507.79 | F45: 88869.71 | G45: 21471 | I45: 226872 | K45: =N45-L45 -> 204265 | L45: 16676 | M45: =L45/N45 -> 0.075477164 | N45: 220941 | O45: 245392 | P45: 285636 | Q45: 174 | R45: =O45/Q45 -> 1410.2989 | S45: 25 | T45: =N45/S45 -> 8837.64 | U45: 31162 | V45: ='$'!C32 -> 2.119044 | W45: =SUM(C45:E45)/V45 -> 67481.657 | X45: =C45/$V45 -> 36828.282 | Y45: =D45/$V45 -> 7762.0191 | Z45: =E45/$V45 -> 22891.356 | AA45: =C45/((N45+U45)*V45) -> 0.14608427 | AB45: =D45/((N45+U45)*V45) -> 0.030789079 | AC45: =E45/((N45+U45)*V45) -> 0.0908016 | AD45: =(C45+D45+E45)/((N45+U45)*V45) -> 0.26767495 | AE45: =(C45+D45+E45)/((K45+U45)*V45) -> 0.28663516 | AF45: =(P45/V45)/K45 -> 0.65990134 | AG45: =F45/($N45+$U45) -> 0.3525135 | AH45: =G45/($N45+$U45) -> 0.08516757 | AI45: =I45/($N45+$U45) -> 0.89991789 | AJ45: =C45/F45 -> 0.87814791 | AK45: =D45/G45 -> 0.76605934 | AL45: =E45/I45 -> 0.21381127 | AN45: =AJ45/$V45 -> 0.41440759 | AO45: =AK45/$V45 -> 0.36151176 | AP45: =AL45/$V45 -> 0.10089987 | AQ45: =AM45/$V45 -> 0
A46: 2014 | B46: 8 | C46: 83325.68 | D46: 18280.89 | E46: 55710.05 | F46: 94887.96 | G46: 24154 | I46: 260557 | K46: =N46-L46 -> 250415 | L46: 20500 | M46: =L46/N46 -> 0.07566949 | N46: 270915 | O46: 267822 | P46: 307878 | Q46: 174 | R46: =O46/Q46 -> 1539.2069 | S46: 28 | T46: =N46/S46 -> 9675.5357 | U46: 18828 | V46: ='$'!C33 -> 2.15926 | W46: =SUM(C46:E46)/V46 -> 72856.729 | X46: =C46/$V46 -> 38589.924 | Y46: =D46/$V46 -> 8466.2755 | Z46: =E46/$V46 -> 25800.529 | AA46: =C46/((N46+U46)*V46) -> 0.13318674 | AB46: =D46/((N46+U46)*V46) -> 0.029219948 | AC46: =E46/((N46+U46)*V46) -> 0.089046254 | AD46: =(C46+D46+E46)/((N46+U46)*V46) -> 0.25145294 | AE46: =(C46+D46+E46)/((K46+U46)*V46) -> 0.27059841 | AF46: =(P46/V46)/K46 -> 0.56939464 | AG46: =F46/($N46+$U46) -> 0.32749009 | AH46: =G46/($N46+$U46) -> 0.083363533 | AI46: =I46/($N46+$U46) -> 0.89926935 | AJ46: =C46/F46 -> 0.87814808 | AK46: =D46/G46 -> 0.75684731 | AL46: =E46/I46 -> 0.21381137 | AN46: =AJ46/$V46 -> 0.40668937 | AO46: =AK46/$V46 -> 0.35051236 | AP46: =AL46/$V46 -> 0.099020671 | AQ46: =AM46/$V46 -> 0
A47: 2014 | B47: 9 | C47: 96420.6 | D47: 21985.19 | E47: 48077.52 | F47: 109799.95 | G47: 29101 | I47: 224859.6 | K47: =N47-L47 -> 315453 | L47: 18625 | M47: =L47/N47 -> 0.055750453 | N47: 334078 | O47: 412224 | P47: 326395 | Q47: 187 | R47: =O47/Q47 -> 2204.4064 | S47: 28 | T47: =N47/S47 -> 11931.357 | U47: 30300 | V47: ='$'!C34 -> 2.213771 | W47: =SUM(C47:E47)/V47 -> 75203.492 | X47: =C47/$V47 -> 43554.912 | Y47: =D47/$V47 -> 9931.104 | Z47: =E47/$V47 -> 21717.477 | AA47: =C47/((N47+U47)*V47) -> 0.11953222 | AB47: =D47/((N47+U47)*V47) -> 0.027254949 | AC47: =E47/((N47+U47)*V47) -> 0.059601504 | AD47: =(C47+D47+E47)/((N47+U47)*V47) -> 0.20638867 | AE47: =(C47+D47+E47)/((K47+U47)*V47) -> 0.21750641 | AF47: =(P47/V47)/K47 -> 0.46738648 | AG47: =F47/($N47+$U47) -> 0.30133529 | AH47: =G47/($N47+$U47) -> 0.079864866 | AI47: =I47/($N47+$U47) -> 0.61710531 | AJ47: =C47/F47 -> 0.87814794 | AK47: =D47/G47 -> 0.75547885 | AL47: =E47/I47 -> 0.21381128 | AN47: =AJ47/$V47 -> 0.39667515 | AO47: =AK47/$V47 -> 0.34126332 | AP47: =AL47/$V47 -> 0.096582386 | AQ47: =AM47/$V47 -> 0
A48: 2014 | B48: 10 | C48: 115280.36 | D48: 21704.39 | E48: 61831.92 | F48: 119678.67 | G48: 28726 | I48: 276514.2 | K48: =N48-L48 -> 289761 | L48: 16714 | M48: =L48/N48 -> 0.054536259 | N48: 306475 | O48: 392664 | P48: 335869 | Q48: 212 | R48: =O48/Q48 -> 1852.1887 | S48: 25 | T48: =N48/S48 -> 12259 | U48: 48007 | V48: ='$'!C35 -> 2.25606 | W48: =SUM(C48:E48)/V48 -> 88125.613 | X48: =C48/$V48 -> 51098.091 | Y48: =D48/$V48 -> 9620.4844 | Z48: =E48/$V48 -> 27407.037 | AA48: =C48/((N48+U48)*V48) -> 0.14414862 | AB48: =D48/((N48+U48)*V48) -> 0.027139557 | AC48: =E48/((N48+U48)*V48) -> 0.077315737 | AD48: =(C48+D48+E48)/((N48+U48)*V48) -> 0.24860391 | AE48: =(C48+D48+E48)/((K48+U48)*V48) -> 0.26090575 | AF48: =(P48/V48)/K48 -> 0.51378254 | AG48: =F48/($N48+$U48) -> 0.33761565 | AH48: =G48/($N48+$U48) -> 0.081036555 | AI48: =I48/($N48+$U48) -> 0.78005146 | AJ48: =C48/F48 -> 0.96324901 | AK48: =D48/G48 -> 0.75556604 | AL48: =E48/I48 -> 0.2236121 | AN48: =AJ48/$V48 -> 0.42696072 | AO48: =AK48/$V48 -> 0.33490512 | AP48: =AL48/$V48 -> 0.099116201 | AQ48: =AM48/$V48 -> 0
A49: 2014 | B49: 11 | C49: 126066.04 | D49: 22161.16 | E49: 69876.31 | F49: 130875.86 | G49: 29336 | I49: 312489 | K49: =N49-L49 -> 308134 | L49: 16022 | M49: =L49/N49 -> 0.049426819 | N49: 324156 | O49: 414277 | P49: 317701 | Q49: 202 | R49: =O49/Q49 -> 2050.8762 | S49: 27 | T49: =N49/S49 -> 12005.778 | U49: 62310 | V49: ='$'!C36 -> 2.232761 | W49: =SUM(C49:E49)/V49 -> 97683.321 | X49: =C49/$V49 -> 56461.95 | Y49: =D49/$V49 -> 9925.451 | Z49: =E49/$V49 -> 31295.92 | AA49: =C49/((N49+U49)*V49) -> 0.1460981 | AB49: =D49/((N49+U49)*V49) -> 0.025682598 | AC49: =E49/((N49+U49)*V49) -> 0.08097975 | AD49: =(C49+D49+E49)/((N49+U49)*V49) -> 0.25276045 | AE49: =(C49+D49+E49)/((K49+U49)*V49) -> 0.26369255 | AF49: =(P49/V49)/K49 -> 0.4617817 | AG49: =F49/($N49+$U49) -> 0.3386478 | AH49: =G49/($N49+$U49) -> 0.075908359 | AI49: =I49/($N49+$U49) -> 0.80858083 | AJ49: =C49/F49 -> 0.96324899 | AK49: =D49/G49 -> 0.75542542 | AL49: =E49/I49 -> 0.22361206 | AN49: =AJ49/$V49 -> 0.43141608 | AO49: =AK49/$V49 -> 0.33833689 | AP49: =AL49/$V49 -> 0.10015047 | AQ49: =AM49/$V49 -> 0
A50: 2014 | B50: 12 | C50: 131972.06 | D50: =27809.83-6094.95 -> 21714.88 | E50: 72037.74 | F50: 137007.2 | G50: 28740 | I50: 322155 | K50: =N50-L50 -> 311688 | L50: 16323 | M50: =L50/N50 -> 0.049763575 | N50: 328011 | O50: 395378 | P50: 335338 | Q50: 221 | R50: =O50/Q50 -> 1789.0407 | S50: 28 | T50: =N50/S50 -> 11714.679 | U50: 67366 | V50: ='$'!C37 -> 2.29694 | W50: =SUM(C50:E50)/V50 -> 98271.91 | X50: =C50/$V50 -> 57455.597 | Y50: =D50/$V50 -> 9453.8299 | Z50: =E50/$V50 -> 31362.482 | AA50: =C50/((N50+U50)*V50) -> 0.14531851 | AB50: =D50/((N50+U50)*V50) -> 0.023910925 | AC50: =E50/((N50+U50)*V50) -> 0.079322981 | AD50: =(C50+D50+E50)/((N50+U50)*V50) -> 0.24855242 | AE50: =(C50+D50+E50)/((K50+U50)*V50) -> 0.2592557 | AF50: =(P50/V50)/K50 -> 0.46839585 | AG50: =F50/($N50+$U50) -> 0.34652294 | AH50: =G50/($N50+$U50) -> 0.072690116 | AI50: =I50/($N50+$U50) -> 0.8148046 | AJ50: =C50/F50 -> 0.96324908 | AK50: =D50/G50 -> 0.75556298 | AL50: =E50/I50 -> 0.22361205 | AN50: =AJ50/$V50 -> 0.41936188 | AO50: =AK50/$V50 -> 0.32894328 | AP50: =AL50/$V50 -> 0.097352151 | AQ50: =AM50/$V50 -> 0
A51: 2015 | B51: 1 | C51: 124111.64 | D51: 24642.82 | E51: 61903.96 | F51: 128846.89 | G51: 26173 | I51: 276836.4 | K51: =N51-L51 -> 259351 | L51: 29157 | M51: =L51/N51 -> 0.10106132 | N51: 288508 | O51: 292253 | P51: 351348 | Q51: 222 | R51: =O51/Q51 -> 1316.455 | S51: 28 | T51: =N51/S51 -> 10303.857 | U51: 50582 | V51: ='$'!C38 -> 2.33742 | W51: =SUM(C51:E51)/V51 -> 90124.334 | X51: =C51/$V51 -> 53097.706 | Y51: =D51/$V51 -> 10542.744 | Z51: =E51/$V51 -> 26483.884 | AA51: =C51/((N51+U51)*V51) -> 0.15658883 | AB51: =D51/((N51+U51)*V51) -> 0.031091285 | AC51: =E51/((N51+U51)*V51) -> 0.078102816 | AD51: =(C51+D51+E51)/((N51+U51)*V51) -> 0.26578293 | AE51: =(C51+D51+E51)/((K51+U51)*V51) -> 0.2907865 | AF51: =(P51/V51)/K51 -> 0.57957922 | AG51: =F51/($N51+$U51) -> 0.37997844 | AH51: =G51/($N51+$U51) -> 0.077185998 | AI51: =I51/($N51+$U51) -> 0.8164098 | AJ51: =C51/F51 -> 0.96324902 | AK51: =D51/G51 -> 0.94153593 | AL51: =E51/I51 -> 0.22361207 | AN51: =AJ51/$V51 -> 0.41209924 | AO51: =AK51/$V51 -> 0.40280991 | AP51: =AL51/$V51 -> 0.095666191 | AQ51: =AM51/$V51 -> 0
...

Sheet UT2 (12334)
A1: Yıl | B1: Ay | C1: Fatura Tutarı TL | F1: Tüketim | I1: GES Üretim | J1: Siparişe Proses Edilen | K1: İşletmelere Proses Edilen | L1: Toplam Proses Edilen İplik | M1: ∑ Paket. Miktarı | N1: ∑ İşçilik | O1: ∑ Kişi Sayısı | P1: Kişi Başı Üretim kg | Q1: Kur: TL/$ | R1: Fatura | S1: Birim Maliyet ($/kg) | X1: İplik Kg Başına Tüketim | AA1: Enerji Birim Fiyatları
C2: DG-117 | D2: S040+S1528 | E2: E0040 | F2: Dgaz Sm3 | G2: Su m3 | H2: Elektrik kW | I2: Elektrik kW | R2: Enerji | S2: Doğalgaz | T2: Su | U2: Elektrik | V2: Toplam Enerji | W2: İşçilik | X2: Dgaz Sm3 | Y2: Su ton | Z2: Elektrik kW | AA2: Dgaz TL/Sm3 | AB2: Su TL/m3 | AC2: Elk TL/kW | AD2: OSB E TL/kW
A3: 2016 | B3: 1 | C3: 11105.78 | D3: =2544.83+39.29 -> 2584.12 | E3: 86082.98 | F3: 11529.5 | G3: =2079+15 -> 2094 | H3: 379834.56 | J3: 155093 | K3: 140630 | L3: =K3+J3 -> 295723 | M3: 140615.2 | N3: 495707 | O3: 221 | P3: =M3/O3 -> 636.26787 | Q3: ='$'!C50 -> 3.001791 | R3: =SUM(C3:E3)/Q3 -> 33237.784 | S3: =(C3/Q3)/M3 -> 0.026310939 | T3: =D3/Q3/M3 -> 0.0061220935 | U3: =E3/Q3/M3 -> 0.20394101 | V3: =(SUM(C3:E3)/Q3)/M3 -> 0.23637405 | W3: =(N3/Q3)/M3 -> 1.17439 | X3: =F3/M3 -> 0.08199327 | Y3: =G3/M3 -> 0.014891704 | Z3: =H3/M3 -> 2.701234 | AA3: =C3/F3 -> 0.96324906 | AB3: =D3/G3 -> 1.2340592 | AC3: =E3/H3 -> 0.22663283
A4: 2016 | B4: 2 | C4: 11367.59 | D4: =2133.82+9 -> 2142.82 | E4: 93717.24 | F4: 11801.3 | G4: =1679+24 -> 1703 | H4: 402900.12 | J4: 216909 | K4: 196408 | L4: =K4+J4 -> 413317 | M4: 196378.6 | N4: 449653 | O4: 215 | P4: =M4/O4 -> 913.38884 | Q4: ='$'!C51 -> 2.945324 | R4: =SUM(C4:E4)/Q4 -> 36406.063 | S4: =(C4/Q4)/M4 -> 0.019653557 | T4: =D4/Q4/M4 -> 0.0037047461 | U4: =E4/Q4/M4 -> 0.16202881 | V4: =(SUM(C4:E4)/Q4)/M4 -> 0.18538712 | W4: =(N4/Q4)/M4 -> 0.77741024 | X4: =F4/M4 -> 0.060094634 | Y4: =G4/M4 -> 0.0086720243 | Z4: =H4/M4 -> 2.0516498 | AA4: =C4/F4 -> 0.96324896 | AB4: =D4/G4 -> 1.2582619 | AC4: =E4/H4 -> 0.23260663
A5: 2016 | B5: 3 | C5: 8930.89 | D5: =1896.46+71.98 -> 1968.44 | E5: 92158.6 | F5: 9271.63 | G5: =1448+27 -> 1475 | H5: 396199.44 | J5: 195681 | K5: 193108 | L5: =K5+J5 -> 388789 | M5: 193082.8 | N5: 494647 | O5: 218 | P5: =M5/O5 -> 885.70092 | Q5: ='$'!C52 -> 2.882802 | R5: =SUM(C5:E5)/Q5 -> 35749.222 | S5: =(C5/Q5)/M5 -> 0.016044875 | T5: =D5/Q5/M5 -> 0.0035364195 | U5: =E5/Q5/M5 -> 0.16556841 | V5: =(SUM(C5:E5)/Q5)/M5 -> 0.1851497 | W5: =(N5/Q5)/M5 -> 0.88866275 | X5: =F5/M5 -> 0.048018933 | Y5: =G5/M5 -> 0.0076392097 | Z5: =H5/M5 -> 2.0519665 | AA5: =C5/F5 -> 0.96324918 | AB5: =D5/G5 -> 1.3345356 | AC5: =E5/H5 -> 0.23260659
A6: 2016 | B6: 4 | C6: 7788.57 | D6: =2202.65+42 -> 2244.65 | E6: 81915.91 | F6: 8085.83 | G6: =1746+111.93 -> 1857.93 | H6: 352164.96 | J6: 174603 | K6: 206958 | L6: =K6+J6 -> 381561 | M6: 206804.7 | N6: 494811 | O6: 216 | P6: =M6/O6 -> 957.42917 | Q6: ='$'!C53 -> 2.834917 | R6: =SUM(C6:E6)/Q6 -> 32434.505 | S6: =(C6/Q6)/M6 -> 0.01328486 | T6: =D6/Q6/M6 -> 0.0038286695 | U6: =E6/Q6/M6 -> 0.13972287 | V6: =(SUM(C6:E6)/Q6)/M6 -> 0.1568364 | W6: =(N6/Q6)/M6 -> 0.84399251 | X6: =F6/M6 -> 0.03909887 | Y6: =G6/M6 -> 0.0089839834 | Z6: =H6/M6 -> 1.7028866 | AA6: =C6/F6 -> 0.96323692 | AB6: =D6/G6 -> 1.2081456 | AC6: =E6/H6 -> 0.23260665
A7: 2016 | B7: 5 | C7: 11451.49 | D7: =2706.14+136.98 -> 2843.12 | E7: 75667.55 | F7: =11806.82+81.79 -> 11888.61 | G7: =2236+51 -> 2287 | H7: 323530.2 | J7: 137202 | K7: 211386 | L7: =K7+J7 -> 348588 | M7: 211305.4 | N7: 516438 | O7: 224 | P7: =M7/O7 -> 943.32768 | Q7: ='$'!C54 -> 2.940724 | R7: =SUM(C7:E7)/Q7 -> 30591.841 | S7: =(C7/Q7)/M7 -> 0.018428803 | T7: =D7/Q7/M7 -> 0.0045754133 | U7: =E7/Q7/M7 -> 0.12177126 | V7: =(SUM(C7:E7)/Q7)/M7 -> 0.14477548 | W7: =(N7/Q7)/M7 -> 0.83110009 | X7: =F7/M7 -> 0.056262689 | Y7: =G7/M7 -> 0.010823197 | Z7: =H7/M7 -> 1.5311024 | AA7: =C7/F7 -> 0.96323203 | AB7: =D7/G7 -> 1.2431657 | AC7: =E7/H7 -> 0.23388095
A8: 2016 | B8: 6 | C8: 11506.41 | D8: =132.3+3083.95 -> 3216.25 | E8: 75707.53 | F8: =11837.02+108.39 -> 11945.41 | G8: =49+2397 -> 2446 | H8: 332569.44 | J8: 135346 | K8: 220068 | L8: =K8+J8 -> 355414 | M8: 218144.6 | N8: 469957 | O8: 221 | P8: =M8/O8 -> 987.07964 | Q8: ='$'!C55 -> 2.914586 | R8: =SUM(C8:E8)/Q8 -> 31026.77 | S8: =(C8/Q8)/M8 -> 0.018097497 | T8: =D8/Q8/M8 -> 0.0050585781 | U8: =E8/Q8/M8 -> 0.11907422 | V8: =(SUM(C8:E8)/Q8)/M8 -> 0.14223029 | W8: =(N8/Q8)/M8 -> 0.73915715 | X8: =F8/M8 -> 0.054759137 | Y8: =G8/M8 -> 0.011212746 | Z8: =H8/M8 -> 1.5245367 | AA8: =C8/F8 -> 0.96324948 | AB8: =D8/G8 -> 1.3149019 | AC8: =E8/H8 -> 0.22764428
A9: 2016 | B9: 7 | C9: 9928.28 | D9: =2446.76 -> 2446.76 | E9: 76513.51 | F9: =10230.08+77.01 -> 10307.09 | G9: =1851 -> 1851 | H9: 336110.04 | J9: 160054 | K9: 192819 | L9: =K9+J9 -> 352873 | M9: 192774.9 | N9: 501510 | O9: 212 | P9: =M9/O9 -> 909.31557 | Q9: ='$'!C56 -> 2.969792 | R9: =SUM(C9:E9)/Q9 -> 29930.901 | S9: =(C9/Q9)/M9 -> 0.017341933 | T9: =D9/Q9/M9 -> 0.0042738065 | U9: =E9/Q9/M9 -> 0.13364774 | V9: =(SUM(C9:E9)/Q9)/M9 -> 0.15526348 | W9: =(N9/Q9)/M9 -> 0.87599793 | X9: =F9/M9 -> 0.053466971 | Y9: =G9/M9 -> 0.0096018724 | Z9: =H9/M9 -> 1.7435363 | AA9: =C9/F9 -> 0.96324763 | AB9: =D9/G9 -> 1.3218585 | AC9: =E9/H9 -> 0.22764423
A10: 2016 | B10: 8 | C10: 11811.13 | D10: =2752.96+183.96 -> 2936.92 | E10: 88810 | F10: =12156.21 -> 12156.21 | G10: =2149+67 -> 2216 | H10: 390126.24 | J10: 226687 | K10: 214611 | L10: =K10+J10 -> 441298 | M10: 214520.3 | N10: 518517 | O10: 220 | P10: =M10/O10 -> 975.09227 | Q10: ='$'!C57 -> 2.960826 | R10: =SUM(C10:E10)/Q10 -> 34976.067 | S10: =(C10/Q10)/M10 -> 0.018595599 | T10: =D10/Q10/M10 -> 0.0046239256 | U10: =E10/Q10/M10 -> 0.13982364 | V10: =(SUM(C10:E10)/Q10)/M10 -> 0.16304316 | W10: =(N10/Q10)/M10 -> 0.81636 | X10: =F10/M10 -> 0.056666945 | Y10: =G10/M10 -> 0.010330025 | Z10: =H10/M10 -> 1.8185982 | AA10: =C10/F10 -> 0.97161286 | AB10: =D10/G10 -> 1.3253249 | AC10: =E10/H10 -> 0.22764426
A11: 2016 | B11: 9 | C11: 7989.81 | D11: =2703.86+117.72 -> 2821.58 | E11: 72541.09 | F11: =8158.23+136.41 -> 8294.64 | G11: =2011+43 -> 2054 | H11: 316484.28 | J11: 177779 | K11: 171601 | L11: =K11+J11 -> 349380 | M11: 171525.3 | N11: 489872 | O11: 216 | P11: =M11/O11 -> 794.09861 | Q11: ='$'!C58 -> 2.968482 | R11: =SUM(C11:E11)/Q11 -> 28079.16 | S11: =(C11/Q11)/M11 -> 0.015691839 | T11: =D11/Q11/M11 -> 0.0055415309 | U11: =E11/Q11/M11 -> 0.14246936 | V11: =(SUM(C11:E11)/Q11)/M11 -> 0.16370273 | W11: =(N11/Q11)/M11 -> 0.96209955 | X11: =F11/M11 -> 0.048358114 | Y11: =G11/M11 -> 0.01197491 | Z11: =H11/M11 -> 1.8451172 | AA11: =C11/F11 -> 0.96324976 | AB11: =D11/G11 -> 1.3737001 | AC11: =E11/H11 -> 0.22920914
A12: 2016 | B12: 10 | C12: 6975.89 | D12: =161.82+3617.74 -> 3779.56 | E12: 101305.88 | F12: =7832.48+114.48 -> 7946.96 | G12: =59+2545 -> 2604 | H12: 430640.28 | J12: 221644 | K12: 263356 | L12: =K12+J12 -> 485000 | M12: 263196.2 | N12: 554182 | O12: 225 | P12: =M12/O12 -> 1169.7609 | Q12: ='$'!C59 -> 3.073362 | R12: =SUM(C12:E12)/Q12 -> 36462.132 | S12: =(C12/Q12)/M12 -> 0.0086239512 | T12: =D12/Q12/M12 -> 0.004672485 | U12: =E12/Q12/M12 -> 0.1252395 | V12: =(SUM(C12:E12)/Q12)/M12 -> 0.13853594 | W12: =(N12/Q12)/M12 -> 0.68510807 | X12: =F12/M12 -> 0.030194053 | Y12: =G12/M12 -> 0.0098937599 | Z12: =H12/M12 -> 1.6361949 | AA12: =C12/F12 -> 0.8778061 | AB12: =D12/G12 -> 1.4514439 | AC12: =E12/H12 -> 0.23524478
A13: 2016 | B13: 11 | C13: 8977.01 | D13: =3653.22+158.59 -> 3811.81 | E13: 109555.85 | F13: =10147.88+93.06 -> 10240.94 | G13: =2654+57 -> 2711 | H13: 477973.44 | J13: 244542 | K13: 227400 | L13: =K13+J13 -> 471942 | M13: 227348.3 | N13: 540567 | O13: 230 | P13: =M13/O13 -> 988.47087 | Q13: ='$'!C60 -> 3.299438 | R13: =SUM(C13:E13)/Q13 -> 37080.457 | S13: =(C13/Q13)/M13 -> 0.011967406 | T13: =D13/Q13/M13 -> 0.0050815893 | U13: =E13/Q13/M13 -> 0.14605078 | V13: =(SUM(C13:E13)/Q13)/M13 -> 0.16309978 | W13: =(N13/Q13)/M13 -> 0.72063914 | X13: =F13/M13 -> 0.045045158 | Y13: =G13/M13 -> 0.011924435 | Z13: =H13/M13 -> 2.1023841 | AA13: =C13/F13 -> 0.87658067 | AB13: =D13/G13 -> 1.4060531 | AC13: =E13/H13 -> 0.22920907
A14: 2016 | B14: 12 | C14: 13518.47 | D14: =195.77+4891.2 -> 5086.97 | E14: 122064.38 | F14: =15283.56+138.24 -> 15421.8 | G14: =70+3711 -> 3781 | H14: 494086.32 | J14: 257508 | K14: 259763 | L14: =K14+J14 -> 517271 | M14: 259709.7 | N14: 557878 | O14: 226 | P14: =M14/O14 -> 1149.158 | Q14: ='$'!C61 -> 3.502333 | R14: =SUM(C14:E14)/Q14 -> 40164.605 | S14: =(C14/Q14)/M14 -> 0.01486216 | T14: =D14/Q14/M14 -> 0.0055925976 | U14: =E14/Q14/M14 -> 0.13419717 | V14: =(SUM(C14:E14)/Q14)/M14 -> 0.15465192 | W14: =(N14/Q14)/M14 -> 0.61332918 | X14: =F14/M14 -> 0.059380916 | Y14: =G14/M14 -> 0.014558563 | Z14: =H14/M14 -> 1.9024562 | AA14: =C14/F14 -> 0.87658185 | AB14: =D14/G14 -> 1.3454033 | AC14: =E14/H14 -> 0.24705072
A15: 2017 | B15: 1 | C15: 8664.09 | D15: =252.72+3601.04 -> 3853.76 | E15: 119052.49 | F15: =9784.14+99.8 -> 9883.94 | G15: =40+2368 -> 2408 | H15: 514951.92 | J15: 207790 | K15: 265977 | L15: =K15+J15 -> 473767 | M15: 263495.3 | N15: 571813 | O15: 235 | P15: =M15/O15 -> 1121.2566 | Q15: ='$'!C62 -> 3.812 | R15: =SUM(C15:E15)/Q15 -> 34514.78 | S15: =(C15/Q15)/M15 -> 0.0086257564 | T15: =D15/Q15/M15 -> 0.0038367093 | U15: =E15/Q15/M15 -> 0.11852575 | V15: =(SUM(C15:E15)/Q15)/M15 -> 0.13098822 | W15: =(N15/Q15)/M15 -> 0.56928306 | X15: =F15/M15 -> 0.037510878 | Y15: =G15/M15 -> 0.0091386829 | Z15: =H15/M15 -> 1.9543116 | AA15: =C15/F15 -> 0.87658262 | AB15: =D15/G15 -> 1.6003987 | AC15: =E15/H15 -> 0.23119147
A16: 2017 | B16: 2 | C16: 13377.14 | D16: =128.4+3482.31 -> 3610.71 | E16: 127903.26 | F16: =15190.55+70.04 -> 15260.59 | G16: =45+2276 -> 2321 | H16: 535298.4 | J16: 179283 | K16: 278691 | L16: =K16+J16 -> 457974 | M16: 275276.2 | N16: 547638 | O16: 240 | P16: =M16/O16 -> 1146.9842 | Q16: ='$'!C63 -> 3.666612 | R16: =SUM(C16:E16)/Q16 -> 39516.346 | S16: =(C16/Q16)/M16 -> 0.013253472 | T16: =D16/Q16/M16 -> 0.0035773299 | U16: =E16/Q16/M16 -> 0.12672083 | V16: =(SUM(C16:E16)/Q16)/M16 -> 0.14355163 | W16: =(N16/Q16)/M16 -> 0.54257522 | X16: =F16/M16 -> 0.055437375 | Y16: =G16/M16 -> 0.0084315317 | Z16: =H16/M16 -> 1.9445866 | AA16: =C16/F16 -> 0.87658079 | AB16: =D16/G16 -> 1.55567 | AC16: =E16/H16 -> 0.23893824
A17: 2017 | B17: 3 | C17: 12630.24 | D17: =210.55+3398.24 -> 3608.79 | E17: 155269.56 | F17: =14180.51+121.57 -> 14302.08 | G17: =32+2203 -> 2235 | H17: 604290.96 | J17: 291961 | K17: 316996 | L17: =K17+J17 -> 608957 | M17: 316993.2 | N17: 635639 | O17: 244 | P17: =M17/O17 -> 1299.1525 | Q17: ='$'!C64 -> 3.599536 | R17: =SUM(C17:E17)/Q17 -> 47647.416 | S17: =(C17/Q17)/M17 -> 0.011069172 | T17: =D17/Q17/M17 -> 0.003162752 | U17: =E17/Q17/M17 -> 0.13607861 | V17: =(SUM(C17:E17)/Q17)/M17 -> 0.15031053 | W17: =(N17/Q17)/M17 -> 0.55707551 | X17: =F17/M17 -> 0.045117939 | Y17: =G17/M17 -> 0.0070506244 | Z17: =H17/M17 -> 1.9063215 | AA17: =C17/F17 -> 0.88310511 | AB17: =D17/G17 -> 1.6146711 | AC17: =E17/H17 -> 0.25694503
A18: 2017 | B18: 4 | C18: 14282.24 | D18: =716.34+3171.27 -> 3887.61 | E18: 146141.05 | F18: =16110.24+59.96 -> 16170.2 | G18: =108+2035 -> 2143 | H18: 568764 | J18: 281171 | K18: 343830 | L18: =K18+J18 -> 625001 | M18: 343174.8 | N18: 638015 | O18: 245 | P18: =M18/O18 -> 1400.7135 | Q18: ='$'!C65 -> 3.653912 | R18: =SUM(C18:E18)/Q18 -> 44968.489 | S18: =(C18/Q18)/M18 -> 0.011389977 | T18: =D18/Q18/M18 -> 0.0031003392 | U18: =E18/Q18/M18 -> 0.11654637 | V18: =(SUM(C18:E18)/Q18)/M18 -> 0.13103669 | W18: =(N18/Q18)/M18 -> 0.50881208 | X18: =F18/M18 -> 0.047119427 | Y18: =G18/M18 -> 0.006244631 | Z18: =H18/M18 -> 1.6573595 | AA18: =C18/F18 -> 0.88324449 | AB18: =D18/G18 -> 1.8140971 | AC18: =E18/H18 -> 0.25694497
A19: 2017 | B19: 5 | C19: 15511.75 | D19: =770.55+3389.52 -> 4160.07 | E19: 145512.34 | F19: =17380.92+179.93 -> 17560.85 | G19: =115+2183 -> 2298 | H19: 566317.08 | J19: 283037 | K19: 316837 | L19: =K19+J19 -> 599874 | M19: 320250.4 | N19: 674284 | O19: 244 | P19: =M19/O19 -> 1312.5016 | Q19: ='$'!C66 -> 3.568617 | R19: =SUM(C19:E19)/Q19 -> 46288.005 | S19: =(C19/Q19)/M19 -> 0.013572854 | T19: =D19/Q19/M19 -> 0.0036400807 | U19: =E19/Q19/M19 -> 0.12732398 | V19: =(SUM(C19:E19)/Q19)/M19 -> 0.14453691 | W19: =(N19/Q19)/M19 -> 0.59000166 | X19: =F19/M19 -> 0.054834748 | Y19: =G19/M19 -> 0.0071756351 | Z19: =H19/M19 -> 1.7683571 | AA19: =C19/F19 -> 0.8833143 | AB19: =D19/G19 -> 1.8103003 | AC19: =E19/H19 -> 0.256945
A20: 2017 | B20: 6 | C20: 15229.82 | D20: =3282.41+380.14 -> 3662.55 | E20: 154482.43 | F20: =16993.9+246.81 -> 17240.71 | G20: =2100+36 -> 2136 | H20: 554898.96 | J20: 227943 | K20: 280194 | L20: =K20+J20 -> 508137 | M20: 277466.9 | N20: 623568 | O20: 254 | P20: =M20/O20 -> 1092.3894 | Q20: ='$'!C67 -> 3.519175 | R20: =SUM(C20:E20)/Q20 -> 49265.751 | S20: =(C20/Q20)/M20 -> 0.015597059 | T20: =D20/Q20/M20 -> 0.0037508657 | U20: =E20/Q20/M20 -> 0.15820749 | V20: =(SUM(C20:E20)/Q20)/M20 -> 0.17755542 | W20: =(N20/Q20)/M20 -> 0.63860421 | X20: =F20/M20 -> 0.062136096 | Y20: =G20/M20 -> 0.0076982155 | Z20: =H20/M20 -> 1.9998744 | AA20: =C20/F20 -> 0.88336385 | AB20: =D20/G20 -> 1.714677 | AC20: =E20/H20 -> 0.2783974
A21: 2017 | B21: 7 | C21: 16797.55 | D21: =3592.15+415.95 -> 4008.1 | E21: 153414.35 | F21: =18857.28+157.37 -> 19014.65 | G21: =61+2340 -> 2401 | H21: 599770.08 | J21: 242795 | K21: 288919 | L21: =K21+J21 -> 531714 | M21: 285695 | N21: 713259 | O21: 264 | P21: =M21/O21 -> 1082.178 | Q21: ='$'!C68 -> 3.556397 | R21: =SUM(C21:E21)/Q21 -> 48987.782 | S21: =(C21/Q21)/M21 -> 0.016532292 | T21: =D21/Q21/M21 -> 0.0039448062 | U21: =E21/Q21/M21 -> 0.15099171 | V21: =(SUM(C21:E21)/Q21)/M21 -> 0.17146881 | W21: =(N21/Q21)/M21 -> 0.70199559 | X21: =F21/M21 -> 0.066555768 | Y21: =G21/M21 -> 0.0084040673 | Z21: =H21/M21 -> 2.099337 | AA21: =C21/F21 -> 0.88340043 | AB21: =D21/G21 -> 1.6693461 | AC21: =E21/H21 -> 0.2557886
A22: 2017 | B22: 8 | C22: 16369.58 | D22: =591.63+4024.51 -> 4616.14 | E22: 156074.32 | F22: =18183.15+346.95 -> 18530.1 | G22: =87+2675 -> 2762 | H22: 604646.28 | J22: 301749 | K22: 305588 | L22: =K22+J22 -> 607337 | M22: 310231.6 | N22: 692928 | O22: 268 | P22: =M22/O22 -> 1157.5806 | Q22: ='$'!C69 -> 3.50946 | R22: =SUM(C22:E22)/Q22 -> 50452.218 | S22: =(C22/Q22)/M22 -> 0.015035269 | T22: =D22/Q22/M22 -> 0.004239871 | U22: =E22/Q22/M22 -> 0.14335245 | V22: =(SUM(C22:E22)/Q22)/M22 -> 0.16262759 | W22: =(N22/Q22)/M22 -> 0.63644632 | X22: =F22/M22 -> 0.059729892 | Y22: =G22/M22 -> 0.008903026 | Z22: =H22/M22 -> 1.9490158 | AA22: =C22/F22 -> 0.88340484 | AB22: =D22/G22 -> 1.6713034 | AC22: =E22/H22 -> 0.258125
A23: 2017 | B23: 9 | C23: 12802.56 | D23: =476.74+2934.83 -> 3411.57 | E23: 140792.4 | F23: =14431.74+59.74 -> 14491.48 | G23: =70+1913 -> 1983 | H23: 560667.24 | J23: 292940 | K23: 287741 | L23: =K23+J23 -> 580681 | M23: 287741 | N23: 704628 | O23: 272 | P23: =M23/O23 -> 1057.8713 | Q23: ='$'!C70 -> 3.467228 | R23: =SUM(C23:E23)/Q23 -> 45283.013 | S23: =(C23/Q23)/M23 -> 0.012832541 | T23: =D23/Q23/M23 -> 0.0034195593 | U23: =E23/Q23/M23 -> 0.14112211 | V23: =(SUM(C23:E23)/Q23)/M23 -> 0.15737421 | W23: =(N23/Q23)/M23 -> 0.70627811 | X23: =F23/M23 -> 0.050362931 | Y23: =G23/M23 -> 0.0068916143 | Z23: =H23/M23 -> 1.9485136 | AA23: =C23/F23 -> 0.88345428 | AB23: =D23/G23 -> 1.7204085 | AC23: =E23/H23 -> 0.2511158
A24: 2017 | B24: 10 | C24: 14369.36 | D24: =2540.84+383.38 -> 2924.22 | E24: 139454 | F24: =15924.64+339.24 -> 16263.88 | G24: =1594+56 -> 1650 | H24: 555337.44 | J24: 261691 | K24: 353516 | L24: =K24+J24 -> 615207 | M24: 345207.2 | N24: 746460 | O24: 280 | P24: =M24/O24 -> 1232.8829 | Q24: ='$'!C71 -> 3.672914 | R24: =SUM(C24:E24)/Q24 -> 42676.627 | S24: =(C24/Q24)/M24 -> 0.01133305 | T24: =D24/Q24/M24 -> 0.0023063193 | U24: =E24/Q24/M24 -> 0.10998675 | V24: =(SUM(C24:E24)/Q24)/M24 -> 0.12362612 | W24: =(N24/Q24)/M24 -> 0.58872969 | X24: =F24/M24 -> 0.047113386 | Y24: =G24/M24 -> 0.0047797381 | Z24: =H24/M24 -> 1.6087076 | AA24: =C24/F24 -> 0.88351365 | AB24: =D24/G24 -> 1.7722545 | AC24: =E24/H24 -> 0.25111579
A25: 2017 | B25: 11 | C25: 17346.77 | D25: =2329.61+427.22 -> 2756.83 | E25: 139367.32 | F25: =19331.6+228.69 -> 19560.29 | G25: =62+1423 -> 1485 | H25: 554992.2 | J25: 296031 | K25: 305789 | L25: =K25+J25 -> 601820 | M25: 283358.2 | N25: 640678 | O25: 247 | P25: =M25/O25 -> 1147.1992 | Q25: ='$'!C72 -> 3.889185 | R25: =SUM(C25:E25)/Q25 -> 41003.686 | S25: =(C25/Q25)/M25 -> 0.015740707 | T25: =D25/Q25/M25 -> 0.0025015869 | U25: =E25/Q25/M25 -> 0.1264639 | V25: =(SUM(C25:E25)/Q25)/M25 -> 0.14470619 | W25: =(N25/Q25)/M25 -> 0.58136037 | X25: =F25/M25 -> 0.069030259 | Y25: =G25/M25 -> 0.0052407165 | Z25: =H25/M25 -> 1.9586241 | AA25: =C25/F25 -> 0.88683603 | AB25: =D25/G25 -> 1.8564512 | AC25: =E25/H25 -> 0.25111582
A26: 2017 | B26: 12 | C26: 18727.8 | D26: =2842.2+427.22 -> 3269.42 | E26: 140133.65 | F26: =20855.66+255.92 -> 21111.58 | G26: =1838 -> 1838 | H26: 558043.92 | J26: 236171 | K26: 380774 | L26: =K26+J26 -> 616945 | M26: 349214.5 | N26: 694464 | O26: 259 | P26: =M26/O26 -> 1348.3185 | Q26: ='$'!C73 -> 3.843316 | R26: =SUM(C26:E26)/Q26 -> 42185.152 | S26: =(C26/Q26)/M26 -> 0.013953668 | T26: =D26/Q26/M26 -> 0.0024359723 | U26: =E26/Q26/M26 -> 0.10441048 | V26: =(SUM(C26:E26)/Q26)/M26 -> 0.12080012 | W26: =(N26/Q26)/M26 -> 0.51742973 | X26: =F26/M26 -> 0.060454477 | Y26: =G26/M26 -> 0.0052632408 | Z26: =H26/M26 -> 1.5979976 | AA26: =C26/F26 -> 0.88708661 | AB26: =D26/G26 -> 1.7787922 | AC26: =E26/H26 -> 0.25111581
A27: 2018 | B27: 1 | C27: 24335.71 | D27: =366.15+3175.69 -> 3541.84 | E27: 160495.25 | F27: =24010.8+288.99 -> 24299.79 | G27: =51+2108 -> 2159 | H27: 635722.92 | J27: 390831 | K27: 332879 | L27: =K27+J27 -> 723710 | M27: 347726.6 | N27: 802832 | O27: 269 | P27: =M27/O27 -> 1292.6639 | Q27: ='$'!C74 -> 3.772753 | R27: =SUM(C27:E27)/Q27 -> 49929.799 | S27: =(C27/Q27)/M27 -> 0.018550163 | T27: =D27/Q27/M27 -> 0.0026998066 | U27: =E27/Q27/M27 -> 0.12233927 | V27: =(SUM(C27:E27)/Q27)/M27 -> 0.14358924 | W27: =(N27/Q27)/M27 -> 0.61196754 | X27: =F27/M27 -> 0.069881884 | Y27: =G27/M27 -> 0.0062089009 | Z27: =H27/M27 -> 1.8282263 | AA27: =C27/F27 -> 1.0014782 | AB27: =D27/G27 -> 1.6405002 | AC27: =E27/H27 -> 0.25246101
A28: 2018 | B28: 2 | C28: 23410.11 | D28: =354.22+2854.55 -> 3208.77 | E28: 153823.48 | F28: =23098.5+244.28 -> 23342.78 | G28: =49+1848 -> 1897 | H28: 562930.2 | J28: 361096 | K28: 272926 | L28: =K28+J28 -> 634022 | M28: 343756.3 | N28: 765154 | O28: 268 | P28: =M28/O28 -> 1282.6728 | Q28: ='$'!C75 -> 3.78455 | R28: =SUM(C28:E28)/Q28 -> 47678.683 | S28: =(C28/Q28)/M28 -> 0.017994449 | T28: =D28/Q28/M28 -> 0.0024664577 | U28: =E28/Q28/M28 -> 0.11823818 | V28: =(SUM(C28:E28)/Q28)/M28 -> 0.13869908 | W28: =(N28/Q28)/M28 -> 0.58814436 | X28: =F28/M28 -> 0.067905025 | Y28: =G28/M28 -> 0.0055184443 | Z28: =H28/M28 -> 1.6375851 | AA28: =C28/F28 -> 1.0028844 | AB28: =D28/G28 -> 1.6914971 | AC28: =E28/H28 -> 0.27325498
A29: 2018 | B29: 3 | C29: 23691.45 | D29: =423.55+3220.15 -> 3643.7 | E29: 153371.75 | F29: =23346.9+272.83 -> 23619.73 | G29: =2144+58 -> 2202 | H29: 561277.08 | J29: 445088 | K29: 216671 | L29: =K29+J29 -> 661759 | M29: 436277.9 | N29: 834545 | O29: 267 | P29: =M29/O29 -> 1633.9996 | Q29: ='$'!C76 -> 3.889189 | R29: =SUM(C29:E29)/Q29 -> 46463.903 | S29: =(C29/Q29)/M29 -> 0.013962699 | T29: =D29/Q29/M29 -> 0.0021474366 | U29: =E29/Q29/M29 -> 0.090390567 | V29: =(SUM(C29:E29)/Q29)/M29 -> 0.1065007 | W29: =(N29/Q29)/M29 -> 0.49184413 | X29: =F29/M29 -> 0.054139185 | Y29: =G29/M29 -> 0.0050472417 | Z29: =H29/M29 -> 1.2865127 | AA29: =C29/F29 -> 1.0030364 | AB29: =D29/G29 -> 1.654723 | AC29: =E29/H29 -> 0.27325497
A30: 2018 | B30: 4 | C30: =18826.17 -> 18826.17 | D30: =308.96+2587.89 -> 2896.85 | E30: 146695.18 | F30: =16913.41+275.93 -> 17189.34 | G30: =42+1588 -> 1630 | H30: 464138.64 | J30: 344050 | K30: 200725 | L30: =K30+J30 -> 544775 | M30: 341333.5 | N30: 778053 | O30: 258 | P30: =M30/O30 -> 1322.9981 | Q30: ='$'!C77 -> 4.060187 | R30: =SUM(C30:E30)/Q30 -> 41480.405 | S30: =(C30/Q30)/M30 -> 0.013584293 | T30: =D30/Q30/M30 -> 0.0020902636 | U30: =E30/Q30/M30 -> 0.10585001 | V30: =(SUM(C30:E30)/Q30)/M30 -> 0.12152456 | W30: =(N30/Q30)/M30 -> 0.56141528 | X30: =F30/M30 -> 0.05035937 | Y30: =G30/M30 -> 0.0047753883 | Z30: =H30/M30 -> 1.3597805 | AA30: =C30/F30 -> 1.0952236 | AB30: =D30/G30 -> 1.7772086 | AC30: =E30/H30 -> 0.31605897
